Workbook
Name RECUPERACIONFISICA: OTICO[RECUPERACION FISICA]

Sheet LISTAS
A2: NEUROLOGICO | B2: DIGESTIVO | C2: RESPIRATORIO | D2: MUSCULOESQUELETICO | E2: GINECOLOGICO | F2: CARDIOVASCULAR | G2: UROLOGICO | H2: OFTALMOLOGICO | I2: ODONTOLOGICO | J2: DERMATOLOGICO | K2: RECUPERACION FISICA
A3: CEFALEA | B3: GASTRITIS | C3: RINOFARINGITIS | D3: MIALGIA | E3: DISMENORREA | F3: HIPERTENSIÓN ARTERIAL | G3: IVU | H3: ASTIGMATISMO | I3: CARIES | J3: PRURITO | K3: BASTON PARA MASAJE
A4: EPILEPSIA | B4: COLITIS | C4: ASMA | D4: MIALGIA MANO | E4: SINDROME PREMENSTRUAL | F4: VARICES | G4: LITIASIS RENAL | H4: CATARATAS | I4: GINGIVITIS | J4: PSORIASIS | K4: RODILLO DE ESPUMA
A5: ECV | B5: REFLUJO GASTROESOFÁGICO | C5: FARINGOAMIGDALITIS | D5: MIALGIA PIE | E5: MIOMAS | F5: HIPOTENSIÓN | G5: CISTITIS | H5: SX DE OJO SECO | I5: PERIODONTITIS | J5: SALPULLIDO | K5: PELOTA DE MASAJE
A6: VERTIGO | B6: ESTRENIMIENTO | C6: NEUMONIA | D6: MIALGIA PIERNA | E6: EMBARAZO | F6: EPISTAXIS | G6: PIELONEFRITIS | H6: CONJUNTIVITIS | I6: AFTAS | J6: ACNE | K6: HIDRATACION
A7: MIGRAÑA | B7: ACIDEZ ESTOMACAL | C7: AMIGDALITIS | D7: LUMBALGIA | H7: BLEFAROESPASMO | I7: HERPES LABIAL | J7: PIE DE ATLETA
A8: TDAH | B8: GASTROENTERITIS | C8: RINITIS ALÉRGICA | D8: DORSALGIA | H8: IRRITACION OCULAR | I8: ODONTALGIA | J8: VERRUGAS
A9: SINCOPE | B9: GASTROCOLITIS | C9: SINUSITIS | D9: CIATALGIA | J9: IRRITACION
A10: CRISIS DE ANSIEDAD | B10: DIABETES MELLITUS TIPO 1 | C10: ODINOFAGIA | D10: ESGUINCE | J10: ROSACEA
A11: ESTRES | B11: DIABETES MELLITUS TIPO 2 | C11: COVID | D11: CERVICALGIA | J11: ABRACION
A12: INSOMNIO | B12: COLACION | C12: OTITIS | D12: GONALGIA | J12: FLICTENA
A13: SOMNOLENCIA | B13: EMESIS | D13: ARTRALGIA | J13: DERMATITIS ALERGIGA
A14: PARESTESIAS | B14: HIPERGLUCEMIA | D14: SX DE TUNEL CARPIANO | J14: DERMATITIS
A15: CONVULSIÓN | B15: HIPOGLUCEMIA | D15: TENDINITIS | J15: PIE DE ATLETA
A16: ADINAMIA | D16: CONTRACTURA MUSCULAR | J16: QUEMADURA
A17: OTALGIA | D17: CONTUSIÓN | J17: UÑA ENTERRADA
D18: MIALGIA TOBILLO | J18: FUEGO LABIAL
D19: MIALGIA HOMBRO
D20: LUXACIÓN
D21: CANSANCIO PIES

Sheet HC
A1: Employee id | B1: Login | C1: shift_pattern_code | D1: supervisor_employee_login
A2: 103427877 | B2: phrna | C2: DB-X0700 | D2: ecortesv
A3: 103979960 | B3: angljua | C3: DJ-X0700 | D3: ferncoar
A4: 106386523 | B4: bocardo | C4: DB-X0700 | D4: feledga
A5: 106783846 | B5: sergita | C5: DB-X0700 | D5: feledga
A6: 107351579 | B6: caldmjos | C6: NF-X1900 | D6: sandmanz
A7: 108021151 | B7: madiazzz | C7: DA-X0700 | D7: hntly
A8: 108592084 | B8: luver | C8: NF-X1900 | D8: camgreci
A9: 110249579 | B9: ruzcvict | C9: DA-X0700 | D9: ferncoar
A10: 110249592 | B10: jomotaco | C10: DB-X0700 | D10: gustbgab
A11: 111261444 | B11: luisfegu | C11: DB-X0700 | D11: hjonan
A12: 111280597 | B12: ramonlco | C12: DB-X0700 | D12: hntly
A13: 111283072 | B13: masusanw | C13: DX-X0700 | D13: ferncoar
... A767: 112913615 | B767: espilizb | C767: DB-X0700 | D767: albertlu

Sheet WHS HOURS
A1: Day | B1: Week | C1: Process Name | D1: Function Name | E1: Employee Type | F1: Employee Id | G1: Name | H1: Manager | I1: Paid Hours-Small(function,employee) | J1: Paid Hours-Medium(function,employee) | K1: Paid Hours-Large(function,employee) | L1: Paid Hours-HeavyBulky(function,employee) | M1: Paid Hours-Total(function,employee) | N1: Status | O1: Login | P1: Aparato | Q1: Dx | R1: Comentarios | S1: Incidentes | T1: Retroalimentaciones | U1: Conteo | W1: Week | X1: (Multiple Items)
A2: 44928 | B2: 1 | C2: Admin/HR/IT | D2: AMCARE NonOcc In | E2: AMZN | F2: 112981009 | G2: Ceja Sanchez,Jonathan | H2: Ledezma,Fer | I2: 0 | J2: 0 | K2: 0 | L2: 0 | M2: 1.08 | N2: =VLOOKUP(F2,HC!A$6:D$100,3,FALSE) -> #N/A | O2: =VLOOKUP(F2,HC!A$6:D$1000,2,FALSE) -> #N/A | P2: NEUROLOGICO | Q2: MIGRAÑA | R2: mareo/dolor de cabeza | U2: =COUNTIF(O$2:O$4999,O2) -> 1395 | Z2: OP2 PLAN | AA2: MONTH | AB2: DAY | AC2: REAL | AF2: DAY | AG2: PER | AH2: GOAL | AI2: CH | AJ2: DAY | AK2: PER | AL2: GOAL | AN2: DAY | AO2: PER | AP2: GOAL | AR2: DAY | AS2: PER | AT2: GOAL | AV2: DAY | AW2: PER | AX2: GOAL | AZ2: DAY | BA2: PER | BB2: GOAL | BD2: DAY | BE2: PER | BF2: GOAL | BH2: DAY | BI2: PER | BJ2: GOAL | BL2: DAY | BM2: PER | BN2: GOAL | BP2: DAY | BQ2: PER | BR2: GOAL | BT2: DAY | BU2: PER | BV2: GOAL
A3: 44928 | B3: 1 | C3: Admin/HR/IT | D3: AMCARE NonOcc In | E3: AMZN | F3: 112950797 | G3: Serna,Denisse | H3: Madrid Molina,Ramon | I3: 0 | J3: 0 | K3: 0 | L3: 0 | M3: 0.32 | N3: =VLOOKUP(F3,HC!A$6:D$100,3,FALSE) -> DA-X0700 | O3: =VLOOKUP(F3,HC!A$6:D$1000,2,FALSE) -> hesdenis | P3: ODONTOLOGICO | Q3: ODONTALGIA | R3: malestar odontologico | U3: =COUNTIF(O$2:O$4999,O3) -> 7 | X3: Sum of Paid Hours-Total(function,employee) | Z3: JAN | AA3: 172 | AB3: =(AA3/31) -> 5.5483871 | AC3: =SUM(AG3:AG32) -> 268.67 | AF3: 44928 | AG3: 3.18 | AH3: 5.55 | AJ3: 44958 | AK3: 10.74 | AL3: 5.26 | AN3: 44986 | AO3: 4.93 | AP3: 5.68 | AR3: 45017 | AS3: 14.87 | AT3: 6.39 | AV3: 45046 | AW3: 2.94 | AX3: 8.71 | AZ3: 45078 | BA3: 8.71 | BB3: 6.3 | BD3: 45108 | BE3: 6.2 | BF3: 7.03 | BH3: 45137 | BI3: 3.11 | BJ3: 7.03 | BL3: 45170 | BM3: 9.02 | BN3: 5.16 | BP3: 45200 | BQ3: 1.91 | BR3: 7.84 | BT3: 45231 | BU3: 18.46 | BV3: 9.9
A4: 44928 | B4: 1 | C4: Admin/HR/IT | D4: AMCARE NonOcc In | E4: AMZN | F4: 112912210 | G4: Fuentes,Jacob | H4: Madrid Molina,Ramon | I4: 0 | J4: 0 | K4: 0 | L4: 0 | M4: 0.03 | N4: =VLOOKUP(F4,HC!A$6:D$100,3,FALSE) -> #N/A | O4: =VLOOKUP(F4,HC!A$6:D$1000,2,FALSE) -> #N/A | P4: CARDIOVASCULAR | Q4: VARICES | R4: varices | U4: =COUNTIF(O$2:O$4999,O4) -> 1395 | W4: afatimae | X4: 2.71 | Z4: FEB | AA4: 163 | AB4: =(AA4/31) -> 5.2580645 | AC4: =SUM(AK3:AK30) -> 226.05 | AF4: 44929 | AG4: 6.27 | AH4: 5.55 | AJ4: 44959 | AK4: 26.56 | AL4: 5.26 | AN4: 44987 | AO4: 10.42 | AP4: 5.68 | AR4: 45018 | AS4: 1.41 | AT4: 6.39 | AV4: 45047 | AW4: 7.37 | AX4: 8.71 | AZ4: 45079 | BA4: 2.63 | BB4: 6.3 | BD4: 45109 | BE4: 2.5 | BF4: 7.03 | BH4: 45138 | BI4: 4.69 | BJ4: 7.03 | BL4: 45171 | BM4: 10.47 | BN4: 5.16 | BP4: 45201 | BQ4: 3.48 | BR4: 7.84 | BT4: 45232 | BU4: 13.32 | BV4: 9.9
A5: 44928 | B5: 1 | C5: Admin/HR/IT | D5: AMCARE NonOcc In | E5: AMZN | F5: 113014195 | G5: Gomez Gutierrez,Vero | H5: Madrid Molina,Ramon | I5: 0 | J5: 0 | K5: 0 | L5: 0 | M5: 0.13 | N5: =VLOOKUP(F5,HC!A$6:D$100,3,FALSE) -> #N/A | O5: =VLOOKUP(F5,HC!A$6:D$1000,2,FALSE) -> #N/A | P5: RESPIRATORIO | Q5: FARINGOAMIGDALITIS | R5: dolor de garganta | U5: =COUNTIF(O$2:O$4999,O5) -> 1395 | W5: #N/A | X5: 31.43 | Z5: MAR | AA5: 176 | AB5: =(AA5/31) -> 5.6774194 | AC5: =SUM(AO3:AO33) -> 246.75 | AF5: 44930 | AG5: 10.4 | AH5: 5.55 | AJ5: 44960 | AK5: 14.23 | AL5: 5.26 | AN5: 44988 | AO5: 5.42 | AP5: 5.68 | AR5: 45019 | AS5: 4.38 | AT5: 6.39 | AV5: 45048 | AW5: 9.72 | AX5: 8.71 | AZ5: 45080 | BA5: 1.54 | BB5: 6.3 | BD5: 45110 | BE5: 3.24 | BF5: 7.03 | BH5: 45139 | BI5: 5.16 | BJ5: 5.81 | BL5: 45172 | BM5: 2.2 | BN5: 5.16 | BP5: 45202 | BQ5: 7.46 | BR5: 7.84 | BT5: 45233 | BU5: 18.52 | BV5: 9.9
A6: 44928 | B6: 1 | C6: Admin/HR/IT | D6: AMCARE NonOcc In | E6: TEMP | F6: 200502532 | G6: Zuniga Saucedo,Estefania | H6: Madrid Molina,Ramon | I6: 0 | J6: 0 | K6: 0 | L6: 0 | M6: 0.22 | N6: =VLOOKUP(F6,HC!A$6:D$100,3,FALSE) -> #N/A | O6: =VLOOKUP(F6,HC!A$6:D$1000,2,FALSE) -> #N/A | P6: NEUROLOGICO | Q6: CEFALEA | R6: dolor de cabeza | U6: =COUNTIF(O$2:O$4999,O6) -> 1395 | W6: mojicemm | X6: 2.82 | Z6: APR | AA6: 198 | AB6: =(AA6/31) -> 6.3870968 | AC6: =SUM(AS3:AS32) -> 175.18 | AF6: 44931 | AG6: 14 | AH6: 5.55 | AJ6: 44961 | AK6: 2.46 | AL6: 5.26 | AN6: 44989 | AO6: 1.71 | AP6: 5.68 | AR6: 45020 | AS6: 14.25 | AT6: 6.39 | AV6: 45049 | AW6: 5.75 | AX6: 8.71 | AZ6: 45081 | BA6: 5.1 | BB6: 6.3 | BD6: 45111 | BE6: 7.58 | BF6: 7.03 | BH6: 45140 | BI6: 4.25 | BJ6: 5.81 | BL6: 45173 | BM6: 2.11 | BN6: 5.16 | BP6: 45203 | BQ6: 5.35 | BR6: 7.84 | BT6: 45234 | BU6: 12.39 | BV6: 9.9
A7: 44928 | B7: 1 | C7: Admin/HR/IT | D7: AMCARE NonOcc In | E7: AMZN | F7: 112980844 | G7: Padilla,Samantha | H7: Hernandez,Nataly | I7: 0 | J7: 0 | K7: 0 | L7: 0 | M7: 0.36 | N7: =VLOOKUP(F7,HC!A$6:D$100,3,FALSE) -> DA-X0700 | O7: =VLOOKUP(F7,HC!A$6:D$1000,2,FALSE) -> samajpad | P7: DIGESTIVO | Q7: GASTROENTERITIS | R7: diarrea | U7: =COUNTIF(O$2:O$4999,O7) -> 20 | W7: jonquija | X7: 2.11 | Z7: MAY | AA7: 270 | AB7: =(AA7/31) -> 8.7096774 | AC7: =SUM(AW3:AW34) -> 224.88 | AF7: 44932 | AG7: 6.07 | AH7: 5.55 | AJ7: 44962 | AK7: 3.28 | AL7: 5.26 | AN7: 44990 | AO7: 4.11 | AP7: 5.68 | AR7: 45021 | AS7: 7.24 | AT7: 6.39 | AV7: 45050 | AW7: 7.09 | AX7: 8.71 | AZ7: 45082 | BA7: 9.91 | BB7: 6.3 | BD7: 45112 | BE7: 5.23 | BF7: 7.03 | BH7: 45141 | BI7: 6.29 | BJ7: 5.81 | BL7: 45174 | BM7: 2.71 | BN7: 5.16 | BP7: 45204 | BQ7: 10.65 | BR7: 7.84 | BT7: 45235 | BU7: 7.82 | BV7: 9.9
A8: 44928 | B8: 1 | C8: Admin/HR/IT | D8: AMCARE NonOcc In | E8: AMZN | F8: 112912663 | G8: Segura,Lucero | H8: Porcar Guri,Albert | I8: 0 | J8: 0 | K8: 0 | L8: 0 | M8: 0.16 | N8: =VLOOKUP(F8,HC!A$6:D$100,3,FALSE) -> #N/A | O8: =VLOOKUP(F8,HC!A$6:D$1000,2,FALSE) -> #N/A | P8: NEUROLOGICO | Q8: CEFALEA | R8: dolor de cabeza | U8: =COUNTIF(O$2:O$4999,O8) -> 1395 | W8: yhernalo | X8: 24.59 | Z8: JUN | AA8: 189 | AB8: =(AA8/30) -> 6.3 | AC8: =SUM(BA3:BA33) -> 131.75 | AF8: 44933 | AG8: 15.36 | AH8: 5.55 | AJ8: 44963 | AK8: 8.15 | AL8: 5.26 | AN8: 44991 | AO8: 4.9 | AP8: 5.68 | AR8: 45022 | AS8: 4.41 | AT8: 6.39 | AV8: 45051 | AW8: 5.15 | AX8: 8.71 | AZ8: 45083 | BA8: 9.32 | BB8: 6.3 | BD8: 45113 | BE8: 2.8 | BF8: 7.03 | BH8: 45142 | BI8: 10.5 | BJ8: 5.81 | BL8: 45175 | BM8: 6.74 | BN8: 5.16 | BP8: 45205 | BQ8: 6.35 | BR8: 7.84 | BT8: 45236 | BU8: 10.2 | BV8: 9.9
A9: 44928 | B9: 1 | C9: Admin/HR/IT | D9: AMCARE NonOcc In | E9: TEMP | F9: 200564823 | G9: Garcia Infante,Sergio | H9: Olmos,Carmen | I9: 0 | J9: 0 | K9: 0 | L9: 0 | M9: 0.88 | N9: =VLOOKUP(F9,HC!A$6:D$100,3,FALSE) -> #N/A | O9: =VLOOKUP(F9,HC!A$6:D$1000,2,FALSE) -> #N/A | P9: DIGESTIVO | Q9: GASTRITIS | R9: dolor de estomago | U9: =COUNTIF(O$2:O$4999,O9) -> 1395 | W9: marcqgon | X9: 3.77 | Z9: JUL | AA9: 218 | AB9: =(AA9/31) -> 7.0322581 | AC9: =SUM(BE3:BE33) -> 152.38 | AF9: 44934 | AG9: 6.16 | AH9: 5.55 | AJ9: 44964 | AK9: 7.99 | AL9: 5.26 | AN9: 44992 | AO9: 9.69 | AP9: 5.68 | AR9: 45023 | AS9: 2.61 | AT9: 6.39 | AV9: 45052 | AW9: 3.89 | AX9: 8.71 | AZ9: 45084 | BA9: 12.03 | BB9: 6.3 | BD9: 45114 | BE9: 2.04 | BF9: 7.03 | BH9: 45143 | BI9: 2.48 | BJ9: 5.81 | BL9: 45176 | BM9: 9.49 | BN9: 5.16 | BP9: 45206 | BQ9: 10.41 | BR9: 7.84 | BT9: 45237 | BU9: 10.48 | BV9: 9.9
A10: 44929 | B10: 1 | C10: Admin/HR/IT | D10: AMCARE NonOcc In | E10: TEMP | F10: 200574329 | G10: Llamas,Jonathan | H10: Gomez Aguado,Jorge | I10: 0 | J10: 0 | K10: 0 | L10: 0 | M10: 0.25 | N10: =VLOOKUP(F10,HC!A$6:D$100,3,FALSE) -> #N/A | O10: =VLOOKUP(F10,HC!A$6:D$1000,2,FALSE) -> #N/A | P10: RESPIRATORIO | Q10: ODINOFAGIA | R10: odinofagia | U10: =COUNTIF(O$2:O$4999,O10) -> 1395 | W10: isafzuni | X10: 5.5 | Z10: AGO | AA10: 180 | AB10: =(AA10/31) -> 5.8064516 | AC10: =SUM(BI3:BI35) -> 145.28 | AF10: 44935 | AG10: 6.39 | AH10: 5.55 | AJ10: 44965 | AK10: 7.72 | AL10: 5.26 | AN10: 44993 | AO10: 6.06 | AP10: 5.68 | AR10: 45024 | AS10: 4.84 | AT10: 6.39 | AV10: 45053 | AW10: 9.24 | AX10: 8.71 | AZ10: 45085 | BA10: 0.3 | BB10: 6.3 | BD10: 45115 | BE10: 2.56 | BF10: 7.03 | BH10: 45144 | BI10: 2.51 | BJ10: 5.81 | BL10: 45177 | BM10: 8.17 | BN10: 5.16 | BP10: 45207 | BQ10: 2.42 | BR10: 7.84 | BT10: 45238 | BU10: 11.98 | BV10: 9.9
A11: 44929 | B11: 1 | C11: Admin/HR/IT | D11: AMCARE NonOcc In | E11: AMZN | F11: 112912008 | G11: Espinosa,Consuelo | H11: Rosas Negrete,Sebastian | I11: 0 | J11: 0 | K11: 0 | L11: 0 | M11: 0.13 | N11: =VLOOKUP(F11,HC!A$6:D$100,3,FALSE) -> #N/A | O11: =VLOOKUP(F11,HC!A$6:D$1000,2,FALSE) -> #N/A | P11: DIGESTIVO | Q11: GASTROENTERITIS | R11: Dolor Abdominal | U11: =COUNTIF(O$2:O$4999,O11) -> 1395 | W11: espilizb | X11: 12.63 | Z11: SEP | AA11: 181 | AB11: =(AA11/31) -> 5.8387097 | AC11: =SUM(BM3:BM32) -> 204.49 | AF11: 44936 | AG11: 5.09 | AH11: 5.55 | AJ11: 44966 | AK11: 7.96 | AL11: 5.26 | AN11: 44994 | AO11: 4.7 | AP11: 5.68 | AR11: 45025 | AS11: 2.7 | AT11: 6.39 | AV11: 45054 | AW11: 15.17 | AX11: 8.71 | AZ11: 45086 | BA11: 4.02 | BB11: 6.3 | BD11: 45116 | BE11: 2.54 | BF11: 7.03 | BH11: 45145 | BI11: 4.86 | BJ11: 5.81 | BL11: 45178 | BM11: 9.76 | BN11: 5.16 | BP11: 45208 | BQ11: 5.52 | BR11: 7.84 | BT11: 45239 | BU11: 11.07 | BV11: 9.9
A12: 44929 | B12: 1 | C12: Admin/HR/IT | D12: AMCARE NonOcc In | E12: AMZN | F12: 113014472 | G12: Ramirez Munoz,Alfredo | H12: Corona Arriaga,Fernando | I12: 0 | J12: 0 | K12: 0 | L12: 0 | M12: 1.67 | N12: =VLOOKUP(F12,HC!A$6:D$100,3,FALSE) -> #N/A | O12: =VLOOKUP(F12,HC!A$6:D$1000,2,FALSE) -> #N/A | R12: Tiempo editado | U12: =COUNTIF(O$2:O$4999,O12) -> 1395 | W12: servelaj | X12: 3.72 | Z12: OCT | AA12: 243 | AB12: =(AA12/31) -> 7.8387097 | AC12: 310.25 | AF12: 44937 | AG12: 11.31 | AH12: 5.55 | AJ12: 44967 | AK12: 9.2 | AL12: 5.26 | AN12: 44995 | AO12: 4.91 | AP12: 5.68 | AR12: 45026 | AS12: 14.56 | AT12: 6.39 | AV12: 45055 | AW12: 5.07 | AX12: 8.71 | AZ12: 45087 | BA12: 1.13 | BB12: 6.3 | BD12: 45117 | BE12: 0.64 | BF12: 7.03 | BH12: 45146 | BI12: 5.71 | BJ12: 5.81 | BL12: 45179 | BM12: 3.07 | BN12: 5.16 | BP12: 45209 | BQ12: 8.3 | BR12: 7.84 | BT12: 45240 | BU12: 15.72 | BV12: 9.9
A13: 44929 | B13: 1 | C13: Admin/HR/IT | D13: AMCARE NonOcc In | E13: TEMP | F13: 200589316 | G13: Torres Zuniga,Daniel | H13: Corona Arriaga,Fernando | I13: 0 | J13: 0 | K13: 0 | L13: 0 | M13: 0.11 | N13: =VLOOKUP(F13,HC!A$6:D$100,3,FALSE) -> #N/A | O13: =VLOOKUP(F13,HC!A$6:D$1000,2,FALSE) -> #N/A | P13: NEUROLOGICO | Q13: CEFALEA | R13: cefalea | U13: =COUNTIF(O$2:O$4999,O13) -> 1395 | W13: sofiawlo | X13: 9.92 | Z13: NOV | AA13: 307 | AB13: =(AA13/31) -> 9.9032258 | AF13: 44938 | AG13: 18.46 | AH13: 5.55 | AJ13: 44968 | AK13: 4.34 | AL13: 5.26 | AN13: 44996 | AO13: 6.75 | AP13: 5.68 | AR13: 45027 | AS13: 4.6 | AT13: 6.39 | AV13: 45056 | AW13: 4.48 | AX13: 8.71 | AZ13: 45088 | BA13: 1.88 | BB13: 6.3 | BD13: 45118 | BE13: 4.24 | BF13: 7.03 | BH13: 45147 | BI13: 2.27 | BJ13: 5.81 | BL13: 45180 | BM13: 6.12 | BN13: 5.16 | BP13: 45210 | BQ13: 11.2 | BR13: 7.84 | BT13: 45241 | BU13: 14.02 | BV13: 9.9
A14: 44929 | B14: 1 | C14: Admin/HR/IT | D14: AMCARE NonOcc In | E14: AMZN | F14: 113014045 | G14: Jaime Perez,Ana | H14: Gomez Aguado,Jorge | I14: 0 | J14: 0 | K14: 0 | L14: 0 | M14: 0.12 | N14: =VLOOKUP(F14,HC!A$6:D$100,3,FALSE) -> #N/A | O14: =VLOOKUP(F14,HC!A$6:D$1000,2,FALSE) -> #N/A | P14: MUSCULOESQUELETICO | Q14: LUMBALGIA | R14: Lumbalgia | U14: =COUNTIF(O$2:O$4999,O14) -> 1395 | W14: Grand Total | X14: 99.2 | Z14: DEC | AA14: 254 | AB14: =(AA14/31) -> 8.1935484 | AF14: 44939 | AG14: 6.05 | AH14: 5.55 | AJ14: 44969 | AK14: 4.42 | AL14: 5.26 | AN14: 44997 | AO14: 7.65 | AP14: 5.68 | AR14: 45028 | AS14: 9.82 | AT14: 6.39 | AV14: 45057 | AW14: 4.92 | AX14: 8.71 | AZ14: 45089 | BA14: 3.65 | BB14: 6.3 | BD14: 45119 | BE14: 4.24 | BF14: 7.03 | BH14: 45148 | BI14: 3.66 | BJ14: 5.81 | BL14: 45181 | BM14: 5.51 | BN14: 5.16 | BP14: 45211 | BQ14: 13.38 | BR14: 7.84 | BT14: 45242 | BU14: 8.8 | BV14: 9.9
A15: 44929 | B15: 1 | C15: Admin/HR/IT | D15: AMCARE NonOcc In | E15: AMZN | F15: 112920666 | G15: Rocha,Jose | H15: Garcia Espejel,Brenda Victoria | I15: 0 | J15: 0 | K15: 0 | L15: 0 | M15: 0.14 | N15: =VLOOKUP(F15,HC!A$6:D$100,3,FALSE) -> D5-X0700 | O15: =VLOOKUP(F15,HC!A$6:D$1000,2,FALSE) -> jorochai | P15: RESPIRATORIO | Q15: RINOFARINGITIS | R15: Rinofaringitis | U15: =COUNTIF(O$2:O$4999,O15) -> 19 | AF15: 44940 | AG15: 4.66 | AH15: 5.55 | AJ15: 44970 | AK15: 8.47 | AL15: 5.26 | AN15: 44998 | AO15: 23.7 | AP15: 5.68 | AR15: 45029 | AS15: 9.57 | AT15: 6.39 | AV15: 45058 | AW15: 4.79 | AX15: 8.71 | AZ15: 45090 | BA15: 3 | BB15: 6.3 | BD15: 45120 | BE15: 7.05 | BF15: 7.03 | BH15: 45149 | BI15: 2.92 | BJ15: 5.81 | BL15: 45182 | BM15: 25.24 | BN15: 5.16 | BP15: 45212 | BQ15: 7.01 | BR15: 7.84 | BT15: 45243 | BU15: 9.61 | BV15: 9.9
A16: 44929 | B16: 1 | C16: Admin/HR/IT | D16: AMCARE NonOcc In | E16: AMZN | F16: 113014011 | G16: Robledo Barrientos,Logan | H16: Robledo Ugarte,Alejandro | I16: 0 | J16: 0 | K16: 0 | L16: 0 | M16: 0.92 | N16: =VLOOKUP(F16,HC!A$6:D$100,3,FALSE) -> #N/A | O16: =VLOOKUP(F16,HC!A$6:D$1000,2,FALSE) -> #N/A | P16: MUSCULOESQUELETICO | Q16: LUMBALGIA | R16: Lumbalgia | U16: =COUNTIF(O$2:O$4999,O16) -> 1395 | AF16: 44941 | AG16: 7.33 | AH16: 5.55 | AJ16: 44971 | AK16: 11.24 | AL16: 5.26 | AN16: 44999 | AO16: 13.64 | AP16: 5.68 | AR16: 45030 | AS16: 3.22 | AT16: 6.39 | AV16: 45059 | AW16: 5.02 | AX16: 8.71 | AZ16: 45091 | BA16: 8.4 | BB16: 6.3 | BD16: 45121 | BE16: 5.5 | BF16: 7.03 | BH16: 45150 | BI16: 4.19 | BJ16: 5.81 | BL16: 45183 | BM16: 11.58 | BN16: 5.16 | BP16: 45213 | BQ16: 6.28 | BR16: 7.84 | BT16: 45244 | BU16: 11.91 | BV16: 9.9
A17: 44929 | B17: 1 | C17: Admin/HR/IT | D17: AMCARE NonOcc In | E17: AMZN | F17: 113101453 | G17: Isaac,Geovanna | H17: Gomez Aguado,Jorge | I17: 0 | J17: 0 | K17: 0 | L17: 0 | M17: 0.14 | N17: =VLOOKUP(F17,HC!A$6:D$100,3,FALSE) -> #N/A | O17: =VLOOKUP(F17,HC!A$6:D$1000,2,FALSE) -> qisgeova | P17: NEUROLOGICO | Q17: CEFALEA | R17: cefalea | U17: =COUNTIF(O$2:O$4999,O17) -> 57 | AF17: 44942 | AG17: 6.88 | AH17: 5.55 | AJ17: 44972 | AK17: 1.75 | AL17: 5.26 | AN17: 45000 | AO17: 13.36 | AP17: 5.68 | AR17: 45031 | AS17: 1.62 | AT17: 6.39 | AV17: 45060 | AW17: 16.3 | AX17: 8.71 | AZ17: 45092 | BA17: 4.12 | BB17: 6.3 | BD17: 45122 | BE17: 5.82 | BF17: 7.03 | BH17: 45151 | BI17: 0.52 | BJ17: 5.81 | BL17: 45184 | BM17: 12.13 | BN17: 5.16 | BP17: 45214 | BQ17: 10.76 | BR17: 7.84 | BT17: 45245 | BU17: 17.81 | BV17: 9.9
A18: 44929 | B18: 1 | C18: Admin/HR/IT | D18: AMCARE NonOcc In | E18: AMZN | F18: 113018997 | G18: Rodriguez Ponce,Gaby | H18: Ledezma,Fer | I18: 0 | J18: 0 | K18: 0 | L18: 0 | M18: 1.62 | N18: =VLOOKUP(F18,HC!A$6:D$100,3,FALSE) -> #N/A | O18: =VLOOKUP(F18,HC!A$6:D$1000,2,FALSE) -> #N/A | P18: DIGESTIVO | Q18: GASTRITIS | R18: Naúseas y vómito, Emb. 12 sdg. | U18: =COUNTIF(O$2:O$4999,O18) -> 1395 | AF18: 44943 | AG18: 7.52 | AH18: 5.55 | AJ18: 44973 | AK18: 6.4 | AL18: 5.26 | AN18: 45001 | AO18: 7.62 | AP18: 5.68 | AR18: 45032 | AS18: 4.89 | AT18: 6.39 | AV18: 45061 | AW18: 8.27 | AX18: 8.71 | AZ18: 45093 | BA18: 1.67 | BB18: 6.3 | BD18: 45123 | BE18: 5.26 | BF18: 7.03 | BH18: 45152 | BI18: 2.37 | BJ18: 5.81 | BL18: 45185 | BM18: 5.41 | BN18: 5.16 | BP18: 45215 | BQ18: 33.22 | BR18: 7.84 | BT18: 45246 | BU18: 10.36 | BV18: 9.9
A19: 44929 | B19: 1 | C19: Admin/HR/IT | D19: AMCARE NonOcc In | E19: AMZN | F19: 112980844 | G19: Padilla,Samantha | H19: Hernandez,Nataly | I19: 0 | J19: 0 | K19: 0 | L19: 0 | M19: 0.35 | N19: =VLOOKUP(F19,HC!A$6:D$100,3,FALSE) -> DA-X0700 | O19: =VLOOKUP(F19,HC!A$6:D$1000,2,FALSE) -> samajpad | P19: NEUROLOGICO | Q19: CEFALEA | R19: cefalea | U19: =COUNTIF(O$2:O$4999,O19) -> 20 | X19: Week | Y19: (Multiple Items) | AF19: 44944 | AG19: 26.61 | AH19: 5.55 | AJ19: 44974 | AK19: 5.93 | AL19: 5.26 | AN19: 45002 | AO19: 7.97 | AP19: 5.68 | AR19: 45033 | AS19: 5.31 | AT19: 6.39 | AV19: 45062 | AW19: 11.77 | AX19: 8.71 | AZ19: 45094 | BA19: 4.54 | BB19: 6.3 | BD19: 45124 | BE19: 10.95 | BF19: 7.03 | BH19: 45153 | BI19: 2.64 | BJ19: 5.81 | BL19: 45186 | BM19: 2.54 | BN19: 5.16 | BP19: 45216 | BQ19: 7.89 | BR19: 7.84 | BT19: 45247 | BU19: 14.79 | BV19: 9.9
A20: 44929 | B20: 1 | C20: Admin/HR/IT | D20: AMCARE NonOcc In | E20: AMZN | F20: 112980862 | G20: Tecla,Alejandro | H20: Robledo Ugarte,Alejandro | I20: 0 | J20: 0 | K20: 0 | L20: 0 | M20: 0.17 | N20: =VLOOKUP(F20,HC!A$6:D$100,3,FALSE) -> #N/A | O20: =VLOOKUP(F20,HC!A$6:D$1000,2,FALSE) -> #N/A | P20: NEUROLOGICO | Q20: ADINAMIA | R20: Adinamia | U20: =COUNTIF(O$2:O$4999,O20) -> 1395 | AF20: 44945 | AG20: 20.99 | AH20: 5.55 | AJ20: 44975 | AK20: 5.15 | AL20: 5.26 | AN20: 45003 | AO20: 4.05 | AP20: 5.68 | AR20: 45034 | AS20: 11.2 | AT20: 6.39 | AV20: 45063 | AW20: 11.14 | AX20: 8.71 | AZ20: 45095 | BA20: 6.67 | BB20: 6.3 | BD20: 45125 | BE20: 19.33 | BF20: 7.03 | BG20: ., | BH20: 45154 | BI20: 7.84 | BJ20: 5.81 | BL20: 45187 | BM20: 3.93 | BN20: 5.16 | BP20: 45217 | BQ20: 9.54 | BR20: 7.84 | BT20: 45248 | BU20: 11.54 | BV20: 9.9
A21: 44929 | B21: 1 | C21: Admin/HR/IT | D21: AMCARE NonOcc In | E21: AMZN | F21: 112912752 | G21: Valderrama Gomez,Leslie | H21: Hernandez,Nataly | I21: 0 | J21: 0 | K21: 0 | L21: 0 | M21: 0.29 | N21: =VLOOKUP(F21,HC!A$6:D$100,3,FALSE) -> NF-X1900 | O21: =VLOOKUP(F21,HC!A$6:D$1000,2,FALSE) -> valderle | P21: MUSCULOESQUELETICO | Q21: MIALGIA PIE | R21: Mialgia pie | U21: =COUNTIF(O$2:O$4999,O21) -> 50 | X21: Row Labels | Y21: Sum of Paid Hours-Total(function,employee) | AF21: 44946 | AG21: 10.14 | AH21: 5.55 | AJ21: 44976 | AK21: 18.49 | AL21: 5.26 | AN21: 45004 | AO21: 2.7 | AP21: 5.68 | AR21: 45035 | AS21: 6.34 | AT21: 6.39 | AV21: 45064 | AW21: 3.22 | AX21: 8.71 | AZ21: 45096 | BA21: 2.11 | BB21: 6.3 | BD21: 45126 | BE21: 9.59 | BF21: 7.03 | BH21: 45155 | BI21: 2.16 | BJ21: 5.81 | BL21: 45188 | BM21: 1.35 | BN21: 5.16 | BP21: 45218 | BQ21: 7.34 | BR21: 7.84 | BT21: 45249 | BU21: 14.22 | BV21: 9.9
A22: 44929 | B22: 1 | C22: Admin/HR/IT | D22: AMCARE NonOcc In | E22: TEMP | F22: 200620341 | G22: Camacho Ramirez,Carlos | H22: Madrid Molina,Ramon | I22: 0 | J22: 0 | K22: 0 | L22: 0 | M22: 0.36 | N22: =VLOOKUP(F22,HC!A$6:D$100,3,FALSE) -> #N/A | O22: =VLOOKUP(F22,HC!A$6:D$1000,2,FALSE) -> #N/A | P22: MUSCULOESQUELETICO | Q22: MIALGIA MANO | R22: mialgia mano | U22: =COUNTIF(O$2:O$4999,O22) -> 1395 | X22: 45231 | Y22: 18.46 | AF22: 44947 | AG22: 9.9 | AH22: 5.55 | AJ22: 44977 | AK22: 13.04 | AL22: 5.26 | AN22: 45005 | AO22: 6.41 | AP22: 5.68 | AR22: 45036 | AS22: 3.44 | AT22: 6.39 | AV22: 45065 | AW22: 5.55 | AX22: 8.71 | AZ22: 45097 | BA22: 2.84 | BB22: 6.3 | BD22: 45127 | BE22: 5.39 | BF22: 7.03 | BH22: 45156 | BI22: 4.25 | BJ22: 5.81 | BL22: 45189 | BM22: 7.69 | BN22: 5.16 | BP22: 45219 | BQ22: 8.22 | BR22: 7.84 | BT22: 45250 | BU22: 10.25 | BV22: 9.9
A23: 44929 | B23: 1 | C23: Admin/HR/IT | D23: AMCARE NonOcc In | E23: AMZN | F23: 200404250 | G23: Hurtado,Caty | H23: Robledo Ugarte,Alejandro | I23: 0 | J23: 0 | K23: 0 | L23: 0 | M23: 0 | N23: =VLOOKUP(F23,HC!A$6:D$100,3,FALSE) -> #N/A | O23: =VLOOKUP(F23,HC!A$6:D$1000,2,FALSE) -> xcathurt | P23: DIGESTIVO | Q23: COLACION | R23: Colación DM1 | U23: =COUNTIF(O$2:O$4999,O23) -> 124 | X23: 45232 | Y23: 13.32 | AF23: 44948 | AG23: 4.15 | AH23: 5.55 | AJ23: 44978 | AK23: 13.07 | AL23: 5.26 | AN23: 45006 | AO23: 14.05 | AP23: 5.68 | AR23: 45037 | AS23: 1.91 | AT23: 6.39 | AV23: 45066 | AW23: 3.53 | AX23: 8.71 | AZ23: 45098 | BA23: 9 | BB23: 6.3 | BD23: 45128 | BE23: 7.21 | BF23: 7.03 | BH23: 45157 | BI23: 3.11 | BJ23: 5.81 | BL23: 45190 | BM23: 6.9 | BN23: 5.16 | BP23: 45220 | BQ23: 8.57 | BR23: 7.84 | BT23: 45251 | BU23: 10.23 | BV23: 9.9
A24: 44930 | B24: 1 | C24: Admin/HR/IT | D24: AMCARE NonOcc In | E24: AMZN | F24: 112971953 | G24: Aguirre Palomino,Ana | H24: Lopez,Alexa | I24: 0 | J24: 0 | K24: 0 | L24: 0 | M24: 0.32 | N24: =VLOOKUP(F24,HC!A$6:D$100,3,FALSE) -> DB-X0700 | O24: =VLOOKUP(F24,HC!A$6:D$1000,2,FALSE) -> anzpalom | P24: CARDIOVASCULAR | Q24: HIPERTENSIÓN ARTERIAL | R24: Valoración | U24: =COUNTIF(O$2:O$4999,O24) -> 14 | X24: 45233 | Y24: 18.52 | AF24: 44949 | AG24: 7.9 | AH24: 5.55 | AJ24: 44979 | AK24: 6.07 | AL24: 5.26 | AN24: 45007 | AO24: 4.81 | AP24: 5.68 | AR24: 45038 | AS24: 3.25 | AT24: 6.39 | AV24: 45067 | AW24: 5.35 | AX24: 8.71 | AZ24: 45099 | BA24: 2.08 | BB24: 6.3 | BD24: 45129 | BE24: 4 | BF24: 7.03 | BH24: 45158 | BI24: 4.87 | BJ24: 5.81 | BL24: 45191 | BM24: 5.19 | BN24: 5.16 | BP24: 45221 | BQ24: 2.44 | BR24: 7.84
A25: 44930 | B25: 1 | C25: Admin/HR/IT | D25: AMCARE NonOcc In | E25: AMZN | F25: 112971953 | G25: Aguirre Palomino,Ana | H25: Lopez,Alexa | I25: 0 | J25: 0 | K25: 0 | L25: 0 | M25: 0.32 | N25: =VLOOKUP(F25,HC!A$6:D$100,3,FALSE) -> DB-X0700 | O25: =VLOOKUP(F25,HC!A$6:D$1000,2,FALSE) -> anzpalom | P25: CARDIOVASCULAR | Q25: HIPERTENSIÓN ARTERIAL | R25: hipertension | U25: =COUNTIF(O$2:O$4999,O25) -> 14 | X25: 45234 | Y25: 12.39 | AF25: 44950 | AG25: 9.37 | AH25: 5.55 | AJ25: 44980 | AK25: 7.23 | AL25: 5.26 | AN25: 45008 | AO25: 8.36 | AP25: 5.68 | AR25: 45039 | AS25: 3.51 | AT25: 6.39 | AV25: 45068 | AW25: 8.05 | AX25: 8.71 | AZ25: 45100 | BA25: 1.19 | BB25: 6.3 | BD25: 45130 | BE25: 4.63 | BF25: 7.03 | BH25: 45159 | BI25: 3.45 | BJ25: 5.81 | BL25: 45192 | BM25: 4.29 | BN25: 5.16 | BP25: 45222 | BQ25: 6.19 | BR25: 7.84
A26: 44930 | B26: 1 | C26: Admin/HR/IT | D26: AMCARE NonOcc In | E26: TEMP | F26: 200513583 | G26: Herrada,Carlos | H26: Olmos,Carmen | I26: 0 | J26: 0 | K26: 0 | L26: 0 | M26: 0.32 | N26: =VLOOKUP(F26,HC!A$6:D$100,3,FALSE) -> #N/A | O26: =VLOOKUP(F26,HC!A$6:D$1000,2,FALSE) -> caherras | P26: DIGESTIVO | Q26: GASTRITIS | R26: dolor estomacal | U26: =COUNTIF(O$2:O$4999,O26) -> 2 | X26: 45235 | Y26: 7.82 | AF26: 44951 | AG26: 6.75 | AH26: 5.55 | AJ26: 44981 | AK26: 3.92 | AL26: 5.26 | AN26: 45009 | AO26: 1.99 | AP26: 5.68 | AR26: 45040 | AS26: 10.24 | AT26: 6.39 | AV26: 45069 | AW26: 13.47 | AX26: 8.71 | AZ26: 45101 | BA26: 1.07 | BB26: 6.3 | BD26: 45131 | BE26: 3.45 | BF26: 7.03 | BH26: 45160 | BI26: 9.04 | BJ26: 5.81 | BL26: 45193 | BM26: 2.68 | BN26: 5.16 | BP26: 45223 | BQ26: 17.65 | BR26: 7.84
A27: 44930 | B27: 1 | C27: Admin/HR/IT | D27: AMCARE NonOcc In | E27: AMZN | F27: 112912008 | G27: Espinosa,Consuelo | H27: Rosas Negrete,Sebastian | I27: 0 | J27: 0 | K27: 0 | L27: 0 | M27: 0.14 | N27: =VLOOKUP(F27,HC!A$6:D$100,3,FALSE) -> #N/A | O27: =VLOOKUP(F27,HC!A$6:D$1000,2,FALSE) -> #N/A | P27: DIGESTIVO | Q27: GASTRITIS | R27: dolor estomacal | U27: =COUNTIF(O$2:O$4999,O27) -> 1395 | X27: 45236 | Y27: 10.02 | AF27: 44952 | AG27: 7.98 | AH27: 5.55 | AJ27: 44982 | AK27: 2.6 | AL27: 5.26 | AN27: 45010 | AO27: 1.94 | AP27: 5.68 | AR27: 45041 | AS27: 5.31 | AT27: 6.39 | AV27: 45070 | AW27: 5.54 | AX27: 8.71 | AZ27: 45102 | BA27: 3.26 | BB27: 6.3 | BD27: 45132 | BE27: 3.59 | BF27: 7.03 | BH27: 45161 | BI27: 6.72 | BJ27: 5.81 | BL27: 45194 | BM27: 2.04 | BN27: 5.16 | BP27: 45224 | BQ27: 9.35 | BR27: 7.84
A28: 44930 | B28: 1 | C28: Admin/HR/IT | D28: AMCARE NonOcc In | E28: AMZN | F28: 113014060 | G28: Diaz Sandoval,Geovanni | H28: Gomez Aguado,Jorge | I28: 0 | J28: 0 | K28: 0 | L28: 0 | M28: 0.34 | N28: =VLOOKUP(F28,HC!A$6:D$100,3,FALSE) -> #N/A | O28: =VLOOKUP(F28,HC!A$6:D$1000,2,FALSE) -> #N/A | P28: MUSCULOESQUELETICO | Q28: LUMBALGIA | R28: Lumbalgia | U28: =COUNTIF(O$2:O$4999,O28) -> 1395 | X28: 45237 | Y28: 10.48 | AF28: 44953 | AG28: 5.21 | AH28: 5.55 | AJ28: 44983 | AK28: 3.82 | AL28: 5.26 | AN28: 45011 | AO28: 4.61 | AP28: 5.68 | AR28: 45042 | AS28: 9.51 | AT28: 6.39 | AV28: 45071 | AW28: 7.09 | AX28: 8.71 | AZ28: 45103 | BA28: 2.77 | BB28: 6.3 | BD28: 45133 | BE28: 1.19 | BF28: 7.03 | BH28: 45162 | BI28: 7.51 | BJ28: 5.81 | BL28: 45195 | BM28: 5.32 | BN28: 5.16 | BP28: 45225 | BQ28: 14.15 | BR28: 7.84
A29: 44930 | B29: 1 | C29: Admin/HR/IT | D29: AMCARE NonOcc In | E29: TEMP | F29: 200514471 | G29: MARTNEZ,EMILIANO | H29: Gomez Aguado,Jorge | I29: 0 | J29: 0 | K29: 0 | L29: 0 | M29: 0.42 | N29: =VLOOKUP(F29,HC!A$6:D$100,3,FALSE) -> #N/A | O29: =VLOOKUP(F29,HC!A$6:D$1000,2,FALSE) -> #N/A | P29: NEUROLOGICO | Q29: CEFALEA | R29: cefalea | U29: =COUNTIF(O$2:O$4999,O29) -> 1395 | X29: 45238 | Y29: 11.95 | AF29: 44954 | AG29: 11.74 | AH29: 5.55 | AJ29: 44984 | AK29: 3.54 | AL29: 5.26 | AN29: 45012 | AO29: 6.29 | AP29: 5.68 | AR29: 45043 | AS29: 4.59 | AT29: 6.39 | AV29: 45072 | AW29: 3.77 | AX29: 8.71 | AZ29: 45104 | BA29: 2.08 | BB29: 6.3 | BD29: 45134 | BE29: 2.7 | BF29: 7.03 | BH29: 45163 | BI29: 5.42 | BJ29: 5.81 | BL29: 45196 | BM29: 10.86 | BN29: 5.16 | BP29: 45226 | BQ29: 44.52 | BR29: 7.84
A30: 44930 | B30: 1 | C30: Admin/HR/IT | D30: AMCARE NonOcc In | E30: AMZN | F30: 113014081 | G30: Frausto,Genesis | H30: Gomez,Abinadab | I30: 0 | J30: 0 | K30: 0 | L30: 0 | M30: 0.25 | N30: =VLOOKUP(F30,HC!A$6:D$100,3,FALSE) -> #N/A | O30: =VLOOKUP(F30,HC!A$6:D$1000,2,FALSE) -> fraugene | P30: NEUROLOGICO | Q30: VERTIGO | R30: Mareo | U30: =COUNTIF(O$2:O$4999,O30) -> 32 | X30: 45239 | Y30: 11.07 | AF30: 44955 | AG30: 2.63 | AH30: 5.55 | AJ30: 44985 | AK30: 8.28 | AL30: 5.26 | AN30: 45013 | AO30: 11.54 | AP30: 5.68 | AR30: 45044 | AS30: 1.89 | AT30: 6.39 | AV30: 45073 | AW30: 2.82 | AX30: 8.71 | AZ30: 45105 | BA30: 4.66 | BB30: 6.3 | BD30: 45135 | BE30: 1.68 | BF30: 7.03 | BH30: 45164 | BI30: 3 | BJ30: 5.81 | BL30: 45197 | BM30: 13.72 | BN30: 5.16 | BP30: 45227 | BQ30: 18.57 | BR30: 7.84
A31: 44930 | B31: 1 | C31: Admin/HR/IT | D31: AMCARE NonOcc In | E31: AMZN | F31: 113003971 | G31: Garcia Ramirez,Gabriel | H31: Piedra,Valentina | I31: 0 | J31: 0 | K31: 0 | L31: 0 | M31: 0.2 | N31: =VLOOKUP(F31,HC!A$6:D$100,3,FALSE) -> #N/A | O31: =VLOOKUP(F31,HC!A$6:D$1000,2,FALSE) -> garamird | P31: NEUROLOGICO | Q31: CEFALEA | R31: cefalea | U31: =COUNTIF(O$2:O$4999,O31) -> 14 | X31: 45240 | Y31: 15.72 | AF31: 44956 | AG31: 5.71 | AH31: 5.55 | AN31: 45014 | AO31: 9.77 | AP31: 5.68 | AR31: 45045 | AS31: 0.75 | AT31: 6.39 | AV31: 45074 | AW31: 7.69 | AX31: 8.71 | AZ31: 45106 | BA31: 5.95 | BB31: 6.3 | BD31: 45136 | BE31: 3.43 | BF31: 7.03 | BH31: 45165 | BI31: 2.25 | BJ31: 5.81 | BL31: 45198 | BM31: 1.69 | BN31: 5.16 | BP31: 45228 | BQ31: 9.09 | BR31: 7.84
A32: 44930 | B32: 1 | C32: Admin/HR/IT | D32: AMCARE NonOcc In | E32: AMZN | F32: 112912210 | G32: Fuentes,Jacob | H32: Madrid Molina,Ramon | I32: 0 | J32: 0 | K32: 0 | L32: 0 | M32: 0.31 | N32: =VLOOKUP(F32,HC!A$6:D$100,3,FALSE) -> #N/A | O32: =VLOOKUP(F32,HC!A$6:D$1000,2,FALSE) -> #N/A | P32: CARDIOVASCULAR | Q32: VARICES | R32: varices | U32: =COUNTIF(O$2:O$4999,O32) -> 1395 | X32: 45241 | Y32: 14.02 | AF32: 44957 | AG32: 4.46 | AH32: 5.55 | AN32: 45015 | AO32: 11.21 | AP32: 5.68 | AR32: 45046 | AS32: 2.94 | AT32: 6.39 | AV32: 45075 | AW32: 8.37 | AX32: 8.71 | AZ32: 45107 | BA32: 6.12 | BB32: 6.3 | BD32: 45137 | BE32: 3.11 | BF32: 7.03 | BH32: 45166 | BI32: 2.36 | BJ32: 5.81 | BL32: 45199 | BM32: 6.56 | BN32: 5.16 | BP32: 45229 | BQ32: 8.94 | BR32: 7.84
A33: 44930 | B33: 1 | C33: Admin/HR/IT | D33: AMCARE NonOcc In | E33: AMZN | F33: 113014113 | G33: Sanchez Villegas,Benjamin | H33: Gomez,Abinadab | I33: 0 | J33: 0 | K33: 0 | L33: 0 | M33: 0.27 | N33: =VLOOKUP(F33,HC!A$6:D$100,3,FALSE) -> #N/A | O33: =VLOOKUP(F33,HC!A$6:D$1000,2,FALSE) -> #N/A | P33: MUSCULOESQUELETICO | Q33: MIALGIA PIE | R33: Mialgia pie | U33: =COUNTIF(O$2:O$4999,O33) -> 1395 | X33: 45242 | Y33: 8.88 | AN33: 45016 | AO33: 21.48 | AP33: 5.68 | AV33: 45076 | AW33: 6.38 | AX33: 8.71 | BD33: 45138 | BE33: 4.69 | BF33: 7.03 | BH33: 45167 | BI33: 5.59 | BJ33: 5.81 | BP33: 45230 | BQ33: 18.45 | BR33: 7.84
A34: 44930 | B34: 1 | C34: Admin/HR/IT | D34: AMCARE NonOcc In | E34: AMZN | F34: 112981061 | G34: Olguin,Claudia | H34: Robledo Ugarte,Alejandro | I34: 0 | J34: 0 | K34: 0 | L34: 0 | M34: 0.15 | N34: =VLOOKUP(F34,HC!A$6:D$100,3,FALSE) -> DA-X0700 | O34: =VLOOKUP(F34,HC!A$6:D$1000,2,FALSE) -> mclaudol | P34: MUSCULOESQUELETICO | Q34: MIALGIA PIE | R34: Mialgia Pie | U34: =COUNTIF(O$2:O$4999,O34) -> 44 | X34: 45243 | Y34: 9.61 | AV34: 45077 | AW34: 5.97 | AX34: 8.71 | BH34: 45168 | BI34: 4.84 | BJ34: 5.81
A35: 44930 | B35: 1 | C35: Admin/HR/IT | D35: AMCARE NonOcc In | E35: AMZN | F35: 112981013 | G35: Lopez Neri,Norma | H35: Ledezma,Fer | I35: 0 | J35: 0 | K35: 0 | L35: 0 | M35: 0.94 | N35: =VLOOKUP(F35,HC!A$6:D$100,3,FALSE) -> DA-X0700 | O35: =VLOOKUP(F35,HC!A$6:D$1000,2,FALSE) -> normaelo | P35: NEUROLOGICO | Q35: CEFALEA | R35: cefalea | U35: =COUNTIF(O$2:O$4999,O35) -> 24 | X35: 45244 | Y35: 11.91 | BH35: 45169 | BI35: 4.74 | BJ35: 5.81
A36: 44930 | B36: 1 | C36: Admin/HR/IT | D36: AMCARE NonOcc In | E36: AMZN | F36: 113014178 | G36: Olvera Munoz,Isabel | H36: Gomez,Abinadab | I36: 0 | J36: 0 | K36: 0 | L36: 0 | M36: 0.13 | N36: =VLOOKUP(F36,HC!A$6:D$100,3,FALSE) -> #N/A | O36: =VLOOKUP(F36,HC!A$6:D$1000,2,FALSE) -> #N/A | P36: NEUROLOGICO | Q36: OTALGIA | R36: otalgia | U36: =COUNTIF(O$2:O$4999,O36) -> 1395 | X36: 45245 | Y36: 17.81
A37: 44930 | B37: 1 | C37: Admin/HR/IT | D37: AMCARE NonOcc In | E37: AMZN | F37: 103427877 | G37: Alanis Hernandez,Patricia | H37: Pizana,Diego | I37: 0 | J37: 0 | K37: 0 | L37: 0 | M37: 0.83 | N37: =VLOOKUP(F37,HC!A$6:D$100,3,FALSE) -> #N/A | O37: =VLOOKUP(F37,HC!A$6:D$1000,2,FALSE) -> #N/A | P37: MUSCULOESQUELETICO | Q37: LUMBALGIA | R37: dolor en espalda | U37: =COUNTIF(O$2:O$4999,O37) -> 1395 | X37: 45246 | Y37: 10.36
A38: 44930 | B38: 1 | C38: Admin/HR/IT | D38: AMCARE NonOcc In | E38: TEMP | F38: 200536194 | G38: Delgado,Bryan | H38: Olmos,Carmen | I38: 0 | J38: 0 | K38: 0 | L38: 0 | M38: 0.95 | N38: =VLOOKUP(F38,HC!A$6:D$100,3,FALSE) -> #N/A | O38: =VLOOKUP(F38,HC!A$6:D$1000,2,FALSE) -> #N/A | P38: MUSCULOESQUELETICO | Q38: MIALGIA | R38: Valoración de restricción | U38: =COUNTIF(O$2:O$4999,O38) -> 1395 | X38: 45247 | Y38: 14.79
A39: 44930 | B39: 1 | C39: Admin/HR/IT | D39: AMCARE NonOcc In | E39: AMZN | F39: 113020655 | G39: Salazar Segura,Raul | H39: Gomez,Abinadab | I39: 0 | J39: 0 | K39: 0 | L39: 0 | M39: 1.49 | N39: =VLOOKUP(F39,HC!A$6:D$100,3,FALSE) -> #N/A | O39: =VLOOKUP(F39,HC!A$6:D$1000,2,FALSE) -> #N/A | P39: NEUROLOGICO | Q39: ADINAMIA | R39: Adinamia | U39: =COUNTIF(O$2:O$4999,O39) -> 1395 | X39: 45248 | Y39: 11.54
A40: 44930 | B40: 1 | C40: Admin/HR/IT | D40: AMCARE NonOcc In | E40: AMZN | F40: 112950784 | G40: Rojas,Samuel | H40: Gomez Aguado,Jorge | I40: 0 | J40: 0 | K40: 0 | L40: 0 | M40: 0.15 | N40: =VLOOKUP(F40,HC!A$6:D$100,3,FALSE) -> NF-X1900 | O40: =VLOOKUP(F40,HC!A$6:D$1000,2,FALSE) -> sarojast | P40: NEUROLOGICO | Q40: VERTIGO | R40: Mareo | U40: =COUNTIF(O$2:O$4999,O40) -> 33 | X40: 45249 | Y40: 14.03
...
